Workbook

Sheet Notes
A1: Notes
A3: HMRC guide to R&D tax credits:
A4: http://www.hmrc.gov.uk/gds/cird/attachments/rdsimpleguide.pdf
A6: Industry funded projects:
A7: - If no risk then large company scheme (RDEC), & only unfunded proportion claimable against R&D tax credits
A8: - If risk (only paid on success) then small company scheme, & only unfunded proportion claimable against R&D tax credits
A10: Under large company scheme subcontracted labour costs are not allowable unless they are carried out by:
A11: - A qualifying body (a charity, an institution of higher education such as a university, a scientific research organisation or a health service body)
A12: - An individual
A13: - A partnership, each member of which is an individual
A15: Under the SME scheme rules sub contracted labour costs are subject to a 65% adjustment and also subject to connected party rules - lower of rate charged by provider or provider's own costs
A16: Note that any materials provided by the sub contractor are not subject to the 65% adjustment but are still subject to the connected party rules
... A38: Benefits in kind provided to R&D workers - e.g. medical insurance cover - are not allowable

Sheet QIA
A1: Qualifying Indirect Activities
A3: Description | B3: Total Cost | D3: R&D
A5: Shared admin / clerical costs:
A6: Payroll | B6: 8500
A7: HR | B7: 4200
A8: Other administration / clerical | B8: 3100
B10: =SUM(B4:B9) -> 15800 | C10: =staff!#ref! -> #NAME? | D10: =B10*C10 -> #NAME?
A12: Dedicated costs:
A13: Admin associated with R&D laboratory leasing | D13: 1200 | G13: NB The actual laboratory leasing cost does not qualify for R&D tax credits
A14: Admin associated with R&D equipment leasing | D14: 800 | G14: NB The actual equipment leasing cost does not qualify for R&D tax credits
A15: Admin associated with R&D equipment maintenance | D15: 600 | G15: NB The actual equipment maintenance cost does not qualify for R&D tax credits
A16: Scientific & technical information services & research | D16: 2400
A17: R&D training | D17: 1800
D20: =SUM(D10:D19) -> #NAME?
A23: HMRC list of qualifying indirect activities:
A24: a. scientific and technical information services, insofar as they are conducted for the purpose of R&D support (such as the preparation of the original report of R&D findings);
A25: b. indirect supporting activities such as maintenance, security, administration and clerical activities, and finance and personnel activities, insofar as undertaken for R&D;
A26: c. ancillary activities essential to the undertaking of R&D (e.g. taking on and paying staff, leasing laboratories and maintaining research and development equipment including computers used for R&D purposes);
A27: d. training required to directly support an R&D project;
A28: e. research by students and researchers carried out at universities;
A29: f. research (including related data collection) to devise new scientific or technological testing, survey, or sampling methods, where this research is not R&D in its own right; and
A30: g. feasibility studies to inform the strategic direction of a specific R&D activity.

Sheet Summary
A1: R&D Tax Credit Claim
A2: NovaTech Solutions Ltd
A3: Tax Reference: 1234567890
A4: Period: 01/01/2024 to 31/12/2024
A6: R&D Periods
A7: Period | B7: From | C7: To | D7: Months
A8: Period 1 | B8: 45292 | C8: 45382 | D8: =IFERROR((DATEDIF(B8, C8, "M")+1), 0) -> 3
A9: Period 2 | B9: 45383 | C9: 45657 | D9: =IFERROR((DATEDIF(B9, C9, "M")+1), 0) -> 9
D10: =SUM(D8:D9) -> 12
A12: R&D Projects
A14: Number | B14: Project Name | C14: Funded? | D14: De Minimis? | E14: Estimate of total R&D Expenditure (%) | F14: Start Date | G14: End Date | Y14: SME
A15: 1 | B15: Automated Document Intelligence Platform | C15: No | D15: No | E15: 0.85 | F15: 45078 | G15: 45657 | Y15: RDEC
A16: 2 | B16: Real-Time Anomaly Detection Engine | C16: No | D16: No | E16: 0.9 | F16: 45292 | G16: 45657 | Y16: De Minimis
A17: 3 | B17: Natural Language Query Interface | C17: No | D17: No | E17: 0.75 | F17: 45352 | G17: 45657
A18: 4 | B18: Predictive Maintenance ML Pipeline | C18: Yes | D18: No | E18: 0.8 | F18: 45170 | G18: 45565
A19: 5 | B19: Privacy-Preserving Data Linkage | C19: No | D19: No | E19: 0.7 | F19: 45444 | G19: 45657 | Y19: Yes
A20: 6 | Y20: No
A21: 7
A22: 8
A23: 9
A24: 10
A25: 11
A26: 12
A28: N.B. The workbook hasn't yet been automated to calculate De Minimis - therefore any de minimis projects will require additional calculations

Sheet Spend by Project
A1: Spend by Project
A3: Cost Category | B3: =IF(Summary!$B$15>0,Summary!$B$15,"") -> Automated Document Intelligence Platform | C3: =IF(Summary!$B$16>0,Summary!$B$16,"") -> Real-Time Anomaly Detection Engine | D3: =IF(Summary!$B$17>0,Summary!$B$17,"") -> Natural Language Query Interface | E3: =IF(Summary!$B$18>0,Summary!$B$18,"") -> Predictive Maintenance ML Pipeline | F3: =IF(Summary!$B$19>0,Summary!$B$19,"") -> Privacy-Preserving Data Linkage | G3: =IF(Summary!$B$20>0,Summary!$B$20,"") | H3: =IF(Summary!$B$21>0,Summary!$B$21,"") | I3: =IF(Summary!$B$22>0,Summary!$B$22,"") | J3: =IF(Summary!$B$23>0,Summary!$B$23,"") | K3: =IF(Summary!$B$24>0,Summary!$B$24,"") | L3: =IF(Summary!$B$25>0,Summary!$B$25,"") | M3: =IF(Summary!$B$26>0,Summary!$B$26,"") | N3: Total | O3: Total | P3: Total
B4: =IF(ISBLANK(Summary!$C$15),"", IF(Summary!$C$15="No", "SME", IF(AND(Summary!$C$15="Yes", Summary!$D$15="Yes"), "De Minimis", "RDEC"))) -> SME | C4: =IF(ISBLANK(Summary!$C$16),"", IF(Summary!$C$16="No", "SME", IF(AND(Summary!$C$16="Yes", Summary!$D$16="Yes"), "De Minimis", "RDEC"))) -> SME | D4: =IF(ISBLANK(Summary!$C$17),"", IF(Summary!$C$17="No", "SME", IF(AND(Summary!$C$17="Yes", Summary!$D$17="Yes"), "De Minimis", "RDEC"))) -> SME | E4: =IF(ISBLANK(Summary!$C$18),"", IF(Summary!$C$18="No", "SME", IF(AND(Summary!$C$18="Yes", Summary!$D$18="Yes"), "De Minimis", "RDEC"))) -> RDEC | F4: =IF(ISBLANK(Summary!$C$19),"", IF(Summary!$C$19="No", "SME", IF(AND(Summary!$C$19="Yes", Summary!$D$19="Yes"), "De Minimis", "RDEC"))) -> SME | G4: =IF(ISBLANK(Summary!$C$20),"", IF(Summary!$C$20="No", "SME", IF(AND(Summary!$C$20="Yes", Summary!$D$20="Yes"), "De Minimis", "RDEC"))) | H4: =IF(ISBLANK(Summary!$C$21),"", IF(Summary!$C$21="No", "SME", IF(AND(Summary!$C$21="Yes", Summary!$D$21="Yes"), "De Minimis", "RDEC"))) | I4: =IF(ISBLANK(Summary!$C$22),"", IF(Summary!$C$22="No", "SME", IF(AND(Summary!$C$22="Yes", Summary!$D$22="Yes"), "De Minimis", "RDEC"))) | J4: =IF(ISBLANK(Summary!$C$23),"", IF(Summary!$C$23="No", "SME", IF(AND(Summary!$C$23="Yes", Summary!$D$23="Yes"), "De Minimis", "RDEC"))) | K4: =IF(ISBLANK(Summary!$C$24),"", IF(Summary!$C$24="No", "SME", IF(AND(Summary!$C$24="Yes", Summary!$D$24="Yes"), "De Minimis", "RDEC"))) | L4: =IF(ISBLANK(Summary!$C$25),"", IF(Summary!$C$25="No", "SME", IF(AND(Summary!$C$25="Yes", Summary!$D$25="Yes"), "De Minimis", "RDEC"))) | M4: =IF(ISBLANK(Summary!$C$26),"", IF(Summary!$C$26="No", "SME", IF(AND(Summary!$C$26="Yes", Summary!$D$26="Yes"), "De Minimis", "RDEC"))) | N4: SME | O4: RDEC
A6: Total:
A7: UK Staff Salaries | B7: =+B26+B43 -> 207641.37 | C7: =+C26+C43 -> 182945.49 | D7: =+D26+D43 -> 122172.16 | E7: =+E26+E43 -> 128104.26 | F7: =+F26+F43 -> 98788.466 | G7: =+G26+G43 -> 0 | H7: =+H26+H43 -> 0 | I7: =+I26+I43 -> 0 | ... M7: =+M26+M43 -> 0 | N7: =SUMIF($B$4:$M$4,$N$4, B7:M7) -> 611547.48 | O7: =SUMIF($B$4:$M$4,$O$4, B7:M7) -> 128104.26 | P7: =SUM(N7:O7) -> 739651.74
A8: Overseas Staff | B8: ='Overseas Staff'!Y905 -> 0 | C8: ='Overseas Staff'!Z905 -> 0 | D8: ='Overseas Staff'!AA905 -> 0 | E8: ='Overseas Staff'!AB905 -> 0 | F8: ='Overseas Staff'!AC905 -> 0 | G8: ='Overseas Staff'!AD905 -> 0 | H8: ='Overseas Staff'!AE905 -> 0 | I8: ='Overseas Staff'!AF905 -> 0 | ... M8: ='Overseas Staff'!AJ905 -> 0 | N8: =SUMIF($B$4:$M$4,$N$4, B8:M8) -> 0 | O8: =SUMIF($B$4:$M$4,$O$4, B8:M8) -> 0 | P8: =SUM(N8:O8) -> 0
A9: Recruitment & Relocation | B9: =IF(B$4="SME", 'Recruitment & Relocation'!X$50*0.65, 'Recruitment & Relocation'!X$50) -> 4348.5 | C9: =IF(C$4="SME", 'Recruitment & Relocation'!Y$50*0.65, 'Recruitment & Relocation'!Y$50) -> 1131 | D9: =IF(D$4="SME", 'Recruitment & Relocation'!Z$50*0.65, 'Recruitment & Relocation'!Z$50) -> 2281.5 | E9: =IF(E$4="SME", 'Recruitment & Relocation'!AA$50*0.65, 'Recruitment & Relocation'!AA$50) -> 1300 | F9: =IF(F$4="SME", 'Recruitment & Relocation'!AB$50*0.65, 'Recruitment & Relocation'!AB$50) -> 1404 | G9: =IF(G$4="SME", 'Recruitment & Relocation'!AC$50*0.65, 'Recruitment & Relocation'!AC$50) -> 0 | H9: =IF(H$4="SME", 'Recruitment & Relocation'!AD$50*0.65, 'Recruitment & Relocation'!AD$50) -> 0 | I9: =IF(I$4="SME", 'Recruitment & Relocation'!AE$50*0.65, 'Recruitment & Relocation'!AE$50) -> 0 | ... M9: =IF(M$4="SME", 'Recruitment & Relocation'!AI$50*0.65, 'Recruitment & Relocation'!AI$50) -> 0 | N9: =SUMIF($B$4:$M$4,$N$4, B9:M9) -> 9165 | O9: =SUMIF($B$4:$M$4,$O$4, B9:M9) -> 1300 | P9: =SUM(N9:O9) -> 10465
A10: Training | B10: =Training!V52 -> 2135 | C10: =Training!W52 -> 2210 | D10: =Training!X52 -> 2355 | E10: =Training!Y52 -> 800 | F10: =Training!Z52 -> 1950 | G10: =Training!AA52 -> 0 | H10: =Training!AB52 -> 0 | I10: =Training!AC52 -> 0 | ... M10: =Training!AG52 -> 0 | N10: =SUMIF($B$4:$M$4,$N$4, B10:M10) -> 8650 | O10: =SUMIF($B$4:$M$4,$O$4, B10:M10) -> 800 | P10: =SUM(N10:O10) -> 9450
A11: Travel & Subsistence | B11: ='Travel & Subsistence'!V101 -> 760.5 | C11: ='Travel & Subsistence'!W101 -> 546.5 | D11: ='Travel & Subsistence'!X101 -> 686.5 | E11: ='Travel & Subsistence'!Y101 -> 353 | F11: ='Travel & Subsistence'!Z101 -> 628.5 | G11: ='Travel & Subsistence'!AA101 -> 0 | H11: ='Travel & Subsistence'!AB101 -> 0 | I11: ='Travel & Subsistence'!AC101 -> 0 | ... M11: ='Travel & Subsistence'!AG101 -> 0 | N11: =SUMIF($B$4:$M$4,$N$4, B11:M11) -> 2622 | O11: =SUMIF($B$4:$M$4,$O$4, B11:M11) -> 353 | P11: =SUM(N11:O11) -> 2975
B12: =SUM(B7:B11) -> 214885.37 | C12: =SUM(C7:C11) -> 186832.99 | D12: =SUM(D7:D11) -> 127495.16 | E12: =SUM(E7:E11) -> 130557.26 | F12: =SUM(F7:F11) -> 102770.97 | G12: =SUM(G7:G11) -> 0 | H12: =SUM(H7:H11) -> 0 | I12: =SUM(I7:I11) -> 0 | ... P12: =SUM(P7:P11) -> 762541.74
A14: EPW | B14: 0 | C14: 0 | D14: 0 | E14: 0 | F14: 0 | G14: 0 | H14: 0 | I14: 0 | J14: 0 | K14: 0 | L14: 0 | M14: 0 | N14: =SUMIF($B$4:$M$4,$N$4, B14:M14) -> 0 | O14: =SUMIF($B$4:$M$4,$O$4, B14:M14) -> 0 | P14: =SUM(N14:O14) -> 0
A15: Clinical Trial Participants | B15: 0 | C15: 0 | D15: 0 | E15: 0 | F15: 0 | G15: 0 | H15: 0 | I15: 0 | J15: 0 | K15: 0 | L15: 0 | M15: 0 | N15: =SUMIF($B$4:$M$4,$N$4, B15:M15) -> 0 | O15: =SUMIF($B$4:$M$4,$O$4, B15:M15) -> 0 | P15: =SUM(N15:O15) -> 0
A16: Software | B16: =Software!V247 -> 11172 | C16: =Software!W247 -> 10930 | D16: =Software!X247 -> 9630 | E16: =Software!Y247 -> 4368 | F16: =Software!Z247 -> 6940 | G16: =Software!AA247 -> 0 | H16: =Software!AB247 -> 0 | I16: =Software!AC247 -> 0 | ... M16: =Software!AG247 -> 0 | N16: =SUMIF($B$4:$M$4,$N$4, B16:M16) -> 38672 | O16: =SUMIF($B$4:$M$4,$O$4, B16:M16) -> 4368 | P16: =SUM(N16:O16) -> 43040
A17: Materials & Consumables | B17: ='Materials and Consumables'!V215+Subcontractors!AS210 -> 9499 | C17: ='Materials and Consumables'!W215+Subcontractors!AT210 -> 19671.5 | D17: ='Materials and Consumables'!X215+Subcontractors!AU210 -> 4513.5 | E17: ='Materials and Consumables'!Y215+Subcontractors!AV210 -> 22356 | F17: ='Materials and Consumables'!Z215+Subcontractors!AW210 -> 7470 | G17: ='Materials and Consumables'!AA215+Subcontractors!AX210 -> 0 | H17: ='Materials and Consumables'!AB215+Subcontractors!AY210 -> 0 | I17: ='Materials and Consumables'!AC215+Subcontractors!AZ210 -> 0 | ... M17: ='Materials and Consumables'!AG215+Subcontractors!BD210 -> 0 | N17: =SUMIF($B$4:$M$4,$N$4, B17:M17) -> 41154 | O17: =SUMIF($B$4:$M$4,$O$4, B17:M17) -> 22356 | P17: =SUM(N17:O17) -> 63510
A18: Sub-Contractors | B18: =IF(B$4="SME", Subcontractors!AB$210*0.65, Subcontractors!AB$210) -> 9404.2 | C18: =IF(C$4="SME", Subcontractors!AC$210*0.65, Subcontractors!AC$210) -> 12166.7 | D18: =IF(D$4="SME", Subcontractors!AD$210*0.65, Subcontractors!AD$210) -> 6825 | E18: =IF(E$4="SME", Subcontractors!AE$210*0.65, Subcontractors!AE$210) -> 1680 | F18: =IF(F$4="SME", Subcontractors!AF$210*0.65, Subcontractors!AF$210) -> 15977 | G18: =IF(G$4="SME", Subcontractors!AG$210*0.65, Subcontractors!AG$210) -> 0 | H18: =IF(H$4="SME", Subcontractors!AH$210*0.65, Subcontractors!AH$210) -> 0 | I18: =IF(I$4="SME", Subcontractors!AI$210*0.65, Subcontractors!AI$210) -> 0 | ... M18: =IF(M$4="SME", Subcontractors!AM$210*0.65, Subcontractors!AM$210) -> 0 | N18: =SUMIF($B$4:$M$4,$N$4, B18:M18) -> 44372.9 | O18: =SUMIF($B$4:$M$4,$O$4, B18:M18) -> 1680 | P18: =SUM(N18:O18) -> 46052.9
A20: Total (£) | B20: =SUM(B12:B19) -> 244960.57 | C20: =SUM(C12:C19) -> 229601.19 | D20: =SUM(D12:D19) -> 148463.66 | E20: =SUM(E12:E19) -> 158961.26 | F20: =SUM(F12:F19) -> 133157.97 | G20: =SUM(G12:G19) -> 0 | H20: =SUM(H12:H19) -> 0 | I20: =SUM(I12:I19) -> 0 | ... P20: =SUM(P12:P19) -> 915144.64
A21: Total SME or RDEC (%) | B21: =IFERROR(IF(B4="SME",B20/$N$20,B20/$O$20),0) -> 0.32394333 | C21: =IFERROR(IF(C4="SME",C20/$N$20,C20/$O$20),0) -> 0.30363163 | D21: =IFERROR(IF(D4="SME",D20/$N$20,D20/$O$20),0) -> 0.19633287 | E21: =IFERROR(IF(E4="SME",E20/$N$20,E20/$O$20),0) -> 1 | F21: =IFERROR(IF(F4="SME",F20/$N$20,F20/$O$20),0) -> 0.17609216 | G21: =IFERROR(IF(G4="SME",G20/$N$20,G20/$O$20),0) -> 0 | H21: =IFERROR(IF(H4="SME",H20/$N$20,H20/$O$20),0) -> 0 | I21: =IFERROR(IF(I4="SME",I20/$N$20,I20/$O$20),0) -> 0 | ... M21: =IFERROR(IF(M4="SME",M20/$N$20,M20/$O$20),0) -> 0 | N21: 1 | O21: 1 | P21: -
A22: Total SME and RDEC (%) | B22: =IFERROR(B20/$P$20, 0) -> 0.26767415 | C22: =IFERROR(C20/$P$20, 0) -> 0.25089061 | D22: =IFERROR(D20/$P$20, 0) -> 0.16222972 | E22: =IFERROR(E20/$P$20, 0) -> 0.17370069 | F22: =IFERROR(F20/$P$20, 0) -> 0.14550483 | G22: =IFERROR(G20/$P$20, 0) -> 0 | H22: =IFERROR(H20/$P$20, 0) -> 0 | I22: =IFERROR(I20/$P$20, 0) -> 0 | ... P22: =IFERROR(P20/$P$20, 0) -> 1
A25: Direct costs:
A26: UK Staff Salaries - Direct | B26: =Staff!AB921 -> 178267.78 | C26: =Staff!AC921 -> 154465.81 | D26: =Staff!AD921 -> 102822.89 | E26: =Staff!AE921 -> 108517.97 | F26: =Staff!AF921 -> 84332.849 | G26: =Staff!AG921 -> 0 | H26: =Staff!AH921 -> 0 | I26: =Staff!AI921 -> 0 | ... M26: =Staff!AM921 -> 0 | N26: =SUMIF($B$4:$M$4,$N$4, B26:M26) -> 519889.33 | O26: =SUMIF($B$4:$M$4,$O$4, B26:M26) -> 108517.97 | P26: =SUM(N26:O26) -> 628407.29
A27: Overseas Staff | B27: =+B8 -> 0 | C27: =+C8 -> 0 | D27: =+D8 -> 0 | E27: =+E8 -> 0 | F27: =+F8 -> 0 | G27: =+G8 -> 0 | H27: =+H8 -> 0 | I27: =+I8 -> 0 | ... M27: =+M8 -> 0 | N27: =SUMIF($B$4:$M$4,$N$4, B27:M27) -> 0 | O27: =SUMIF($B$4:$M$4,$O$4, B27:M27) -> 0 | P27: =SUM(N27:O27) -> 0
A28: Recruitment & Relocation | B28: =+B9 -> 4348.5 | C28: =+C9 -> 1131 | D28: =+D9 -> 2281.5 | E28: =+E9 -> 1300 | F28: =+F9 -> 1404 | G28: =+G9 -> 0 | H28: =+H9 -> 0 | I28: =+I9 -> 0 | ... M28: =+M9 -> 0 | N28: =SUMIF($B$4:$M$4,$N$4, B28:M28) -> 9165 | O28: =SUMIF($B$4:$M$4,$O$4, B28:M28) -> 1300 | P28: =SUM(N28:O28) -> 10465
A29: Training | B29: =+B10 -> 2135 | C29: =+C10 -> 2210 | D29: =+D10 -> 2355 | E29: =+E10 -> 800 | F29: =+F10 -> 1950 | G29: =+G10 -> 0 | H29: =+H10 -> 0 | I29: =+I10 -> 0 | ... M29: =+M10 -> 0 | N29: =SUMIF($B$4:$M$4,$N$4, B29:M29) -> 8650 | O29: =SUMIF($B$4:$M$4,$O$4, B29:M29) -> 800 | P29: =SUM(N29:O29) -> 9450
A30: Travel & Subsistence | B30: =+B11 -> 760.5 | C30: =+C11 -> 546.5 | D30: =+D11 -> 686.5 | E30: =+E11 -> 353 | F30: =+F11 -> 628.5 | G30: =+G11 -> 0 | H30: =+H11 -> 0 | I30: =+I11 -> 0 | ... M30: =+M11 -> 0 | N30: =SUMIF($B$4:$M$4,$N$4, B30:M30) -> 2622 | O30: =SUMIF($B$4:$M$4,$O$4, B30:M30) -> 353 | P30: =SUM(N30:O30) -> 2975
C31: =SUM(C26:C30) -> 158353.31 | D31: =SUM(D26:D30) -> 108145.89 | E31: =SUM(E26:E30) -> 110970.97 | F31: =SUM(F26:F30) -> 88315.349 | G31: =SUM(G26:G30) -> 0 | H31: =SUM(H26:H30) -> 0 | I31: =SUM(I26:I30) -> 0 | J31: =SUM(J26:J30) -> 0 | ... P31: =SUM(P26:P30) -> 651297.29
A33: EPW | B33: =+B14 -> 0 | C33: =+C14 -> 0 | D33: =+D14 -> 0 | E33: =+E14 -> 0 | F33: =+F14 -> 0 | G33: =+G14 -> 0 | H33: =+H14 -> 0 | I33: =+I14 -> 0 | ... M33: =+M14 -> 0 | N33: =SUMIF($B$4:$M$4,$N$4, B33:M33) -> 0 | O33: =SUMIF($B$4:$M$4,$O$4, B33:M33) -> 0 | P33: =SUM(N33:O33) -> 0
A34: Clinical Trial Participants | B34: =+B15 -> 0 | C34: =+C15 -> 0 | D34: =+D15 -> 0 | E34: =+E15 -> 0 | F34: =+F15 -> 0 | G34: =+G15 -> 0 | H34: =+H15 -> 0 | I34: =+I15 -> 0 | ... M34: =+M15 -> 0 | N34: =SUMIF($B$4:$M$4,$N$4, B34:M34) -> 0 | O34: =SUMIF($B$4:$M$4,$O$4, B34:M34) -> 0 | P34: =SUM(N34:O34) -> 0
A35: Software | B35: =+B16 -> 11172 | C35: =+C16 -> 10930 | D35: =+D16 -> 9630 | E35: =+E16 -> 4368 | F35: =+F16 -> 6940 | G35: =+G16 -> 0 | H35: =+H16 -> 0 | I35: =+I16 -> 0 | ... M35: =+M16 -> 0 | N35: =SUMIF($B$4:$M$4,$N$4, B35:M35) -> 38672 | O35: =SUMIF($B$4:$M$4,$O$4, B35:M35) -> 4368 | P35: =SUM(N35:O35) -> 43040
A36: Materials & Consumables | B36: =+B17 -> 9499 | C36: =+C17 -> 19671.5 | D36: =+D17 -> 4513.5 | E36: =+E17 -> 22356 | F36: =+F17 -> 7470 | G36: =+G17 -> 0 | H36: =+H17 -> 0 | I36: =+I17 -> 0 | ... M36: =+M17 -> 0 | N36: =SUMIF($B$4:$M$4,$N$4, B36:M36) -> 41154 | O36: =SUMIF($B$4:$M$4,$O$4, B36:M36) -> 22356 | P36: =SUM(N36:O36) -> 63510
A37: Sub-Contractors | B37: =+B18 -> 9404.2 | C37: =+C18 -> 12166.7 | D37: =+D18 -> 6825 | E37: =+E18 -> 1680 | F37: =+F18 -> 15977 | G37: =+G18 -> 0 | H37: =+H18 -> 0 | I37: =+I18 -> 0 | ... M37: =+M18 -> 0 | N37: =SUMIF($B$4:$M$4,$N$4, B37:M37) -> 44372.9 | O37: =SUMIF($B$4:$M$4,$O$4, B37:M37) -> 1680 | P37: =SUM(N37:O37) -> 46052.9
A39: Total direct costs (£) | B39: =SUM(B31:B38) -> 30075.2 | C39: =SUM(C31:C38) -> 201121.51 | D39: =SUM(D31:D38) -> 129114.39 | E39: =SUM(E31:E38) -> 139374.97 | F39: =SUM(F31:F38) -> 118702.35 | G39: =SUM(G31:G38) -> 0 | H39: =SUM(H31:H38) -> 0 | I39: =SUM(I31:I38) -> 0 | ... P39: =SUM(P31:P38) -> 803900.19
A42: Indirect costs:
A43: UK Staff Salaries - Indirect | B43: =Staff!AR921 -> 29373.586 | C43: =Staff!AS921 -> 28479.686 | D43: =Staff!AT921 -> 19349.265 | E43: =Staff!AU921 -> 19586.291 | F43: =Staff!AV921 -> 14455.617 | G43: =Staff!AW921 -> 0 | H43: =Staff!AX921 -> 0 | I43: =Staff!AY921 -> 0 | ... M43: =Staff!BC921 -> 0 | N43: =SUMIF($B$4:$M$4,$N$4, B43:M43) -> 91658.155 | O43: =SUMIF($B$4:$M$4,$O$4, B43:M43) -> 19586.291 | P43: =SUM(N43:O43) -> 111244.45
A44: Overseas Staff | B44: 0 | C44: 0 | D44: 0 | E44: 0 | F44: 0 | G44: 0 | H44: 0 | I44: 0 | J44: 0 | K44: 0 | L44: 0 | M44: 0 | N44: =SUMIF($B$4:$M$4,$N$4, B44:M44) -> 0 | O44: =SUMIF($B$4:$M$4,$O$4, B44:M44) -> 0 | P44: =SUM(N44:O44) -> 0
A45: Recruitment & Relocation | B45: 0 | C45: 0 | D45: 0 | E45: 0 | F45: 0 | G45: 0 | H45: 0 | I45: 0 | J45: 0 | K45: 0 | L45: 0 | M45: 0 | N45: =SUMIF($B$4:$M$4,$N$4, B45:M45) -> 0 | O45: =SUMIF($B$4:$M$4,$O$4, B45:M45) -> 0 | P45: =SUM(N45:O45) -> 0
A46: Training | B46: 0 | C46: 0 | D46: 0 | E46: 0 | F46: 0 | G46: 0 | H46: 0 | I46: 0 | J46: 0 | K46: 0 | L46: 0 | M46: 0 | N46: =SUMIF($B$4:$M$4,$N$4, B46:M46) -> 0 | O46: =SUMIF($B$4:$M$4,$O$4, B46:M46) -> 0 | P46: =SUM(N46:O46) -> 0
A47: Travel & Subsistence | B47: 0 | C47: 0 | D47: 0 | E47: 0 | F47: 0 | G47: 0 | H47: 0 | I47: 0 | J47: 0 | K47: 0 | L47: 0 | M47: 0 | N47: =SUMIF($B$4:$M$4,$N$4, B47:M47) -> 0 | O47: =SUMIF($B$4:$M$4,$O$4, B47:M47) -> 0 | P47: =SUM(N47:O47) -> 0
B48: 0 | C48: 0 | D48: 0 | E48: 0 | F48: 0 | G48: 0 | H48: 0 | I48: 0 | J48: 0 | K48: 0 | L48: 0 | M48: 0 | N48: =SUM(N43:N47) -> 91658.155 | O48: =SUM(O43:O47) -> 19586.291 | P48: =SUM(P43:P47) -> 111244.45
A50: EPW | B50: 0 | C50: 0 | D50: 0 | E50: 0 | F50: 0 | G50: 0 | H50: 0 | I50: 0 | J50: 0 | K50: 0 | L50: 0 | M50: 0 | N50: =SUMIF($B$4:$M$4,$N$4, B50:M50) -> 0 | O50: =SUMIF($B$4:$M$4,$O$4, B50:M50) -> 0 | P50: =SUM(N50:O50) -> 0
A51: Clinical Trial Participants | B51: 0 | C51: 0 | D51: 0 | E51: 0 | F51: 0 | G51: 0 | H51: 0 | I51: 0 | J51: 0 | K51: 0 | L51: 0 | M51: 0 | N51: =SUMIF($B$4:$M$4,$N$4, B51:M51) -> 0 | O51: =SUMIF($B$4:$M$4,$O$4, B51:M51) -> 0 | P51: =SUM(N51:O51) -> 0
...

Sheet R&D Calculation (OLD)
A1: R&D Tax Credit Claim
A2: =Summary!A2 -> NovaTech Solutions Ltd
A3: =Summary!A3 -> Tax Reference: 1234567890
A5: =Summary!A4 -> Period: 01/01/2024 to 31/12/2024
D7: Total
A9: SME Scheme | D9: Spend | E9: Allowable % | F9: Allowable Spend | H9: Period 1 | I9: Period 2 | J9: Check
H10: 44743 | I10: 45017
H11: 45016 | I11: 45107
A13: UK staff costs | D13: =Staff!AO921+Staff!BE921 -> 611547.48 | E13: 1 | F13: =D13*E13 -> 611547.48 | J13: =+D13-H13-I13 -> 611547.48
A14: Overseas staff costs | D14: ='Overseas Staff'!AL905 -> 0 | E14: 1 | F14: =D14*E14 -> 0 | J14: =+D14-H14-I14 -> 0
A15: Recruitment & relocation | D15: ='Recruitment & Relocation'!AK50 -> 14100 | E15: 0.65 | F15: =D15*E15 -> 9165 | H15: =SUMIFS('Recruitment & Relocation'!AK7:AK48, 'Recruitment & Relocation'!A7:A48, ">="&H10, 'Recruitment & Relocation'!A7:A48, "<="&H11)*0.65 -> 0 | I15: =SUMIFS('Recruitment & Relocation'!AK7:AK48, 'Recruitment & Relocation'!A7:A48, ">="&I10, 'Recruitment & Relocation'!A7:A48, "<="&I11)*0.65 -> 0 | J15: =+F15-H15-I15 -> 9165
A16: Training | D16: =Training!AI52 -> 8650 | E16: 1 | F16: =D16*E16 -> 8650 | J16: =+D16-H16-I16 -> 8650
A17: Travel & subsistence (Out of pocket expenses only) | D17: ='Travel & Subsistence'!AI101 -> 2622 | E17: 1 | F17: =D17*E17 -> 2622 | J17: =+D17-H17-I17 -> 2622
A18: Software | D18: =Software!AI247 -> 38672 | E18: 1 | F18: =D18*E18 -> 38672 | J18: =+D18-H18-I18 -> 38672
A19: Materials & consumables | D19: ='Materials and Consumables'!AI215+Subcontractors!BF210 -> 41154 | E19: 1 | F19: =D19*E19 -> 41154 | J19: =+D19-H19-I19 -> 41154
A20: Sub contractors (Connected parties) | D20: =+Subcontractors!AO210 -> 0 | E20: 1 | F20: =D20*E20 -> 0 | J20: =+D20-H20-I20 -> 0
A21: Sub contractors (Unconnected parties) | D21: =+Subcontractors!AP210 -> 68266 | E21: 0.65 | F21: =D21*E21 -> 44372.9
A22: Total relevant net expenditure | D22: =SUM(D13:D21) -> 785011.48 | F22: =SUM(F13:F21) -> 756183.38 | H22: =SUM(H13:H21) -> 0 | I22: =SUM(I13:I21) -> 0
A24: Claim for enhancement: | B24: No. of Mths
A25: Jul 2022 - Mar 2023 | B25: 9 | E25: 1.3 | F25: =(F22/$B$27*$B$25)*$E$25 -> 737278.8 | H25: =+H22*E25 -> 0 | I25: 0
A26: Apr 2023 - Jun 2023 | B26: 3 | E26: 0.86 | F26: =(F22/$B$27*$B$26)*$E$26 -> 162579.43 | H26: 0 | I26: =+I22*E26 -> 0
A27: Total | B27: =SUM(B25:B26) -> 12 | F27: =F25+F26 -> 899858.22 | H27: =H25+H26 -> 0 | I27: =I25+I26 -> 0
A30: Normal taxable profit / (loss) on ordinary activities | B30: TBC | F30: 0
A33: Trading loss (after R&D Relief) | B33: A | F33: =IF((-F30+F27)>0,-F30+F27,0) -> 899858.22
A35: Total enhanced R&D spend | B35: B | F35: =F22+F27 -> 1656041.6
A37: Loss qualifying for conversion to repayable credits | B37: Lower of A or B | F37: =IF(F33<F35,F33,F35) -> 899858.22
A40: Payable tax credit under SME scheme
A42: =A25 -> Jul 2022 - Mar 2023 | D42: =((($F$37)/B27*B25)) -> 674893.67 | E42: 0.145 | F42: =D42*E42 -> 97859.582 | H42: =((($F$37)/B27*B25)) -> 674893.67 | I42: =((($F$37)/M27*M25)) -> #DIV/0! | L42: SME intensive test
A43: =A26 -> Apr 2023 - Jun 2023 | D43: =((($F$37)/B27*B26)) -> 224964.56 | E43: 0.1 | F43: =D43*E43 -> 22496.456 | H43: =((($F$37)/L27*L26)) -> #DIV/0! | I43: =((($F$37)/M27*M26)) -> #DIV/0! | L43: Total R&D expenditure | O43: 1
A44: =+A43 -> Apr 2023 - Jun 2023 | E44: 0.045 | F44: =IF(O45>0.4, D43*E44, 0) -> 10123.405 | L44: Total CT eligible expenditure | O44: 1
D45: =SUM(D42:D43) -> 899858.22 | F45: =SUM(F42:F44) -> 130479.44 | H45: =SUM(H42:H43) -> #DIV/0! | I45: =SUM(I42:I43) -> #DIV/0! | O45: =+O43/O44 -> 1
A48: RDEC Scheme | D48: Spend | E48: % Allowable | F48: Allowable Spend
A50: Expenditure on R&D for which Innovate UK grants received:
A51: UK staff costs | D51: =Staff!AN921+Staff!BD921 -> 128104.26 | E51: 1 | F51: =D51*E51 -> 128104.26
A52: Overseas staff costs | D52: ='Overseas Staff'!AK905 -> 0 | E52: 1 | F52: =D52*E52 -> 0
A53: Recruitment & relocation | D53: ='Recruitment & Relocation'!AJ50 -> 1300 | E53: 1 | F53: =D53*E53 -> 1300
A54: Training | D54: =Training!AH52 -> 800 | E54: 1 | F54: =D54*E54 -> 800
A55: Travel & subsistence (out of pocket expenses only) | D55: ='Travel & Subsistence'!AH101 -> 353 | E55: 1 | F55: =D55*E55 -> 353
A56: Software | D56: =Software!AH247 -> 4368 | E56: 1 | F56: =D56*E56 -> 4368
A57: Materials & consumables | D57: ='Materials and Consumables'!AH215+Subcontractors!BE210 -> 22356 | E57: 1 | F57: =D57*E57 -> 22356
...

Sheet R&D Calculation
A1: R&D Calculation
A2: =Summary!A2 -> NovaTech Solutions Ltd
A3: =Summary!A3 -> Tax Reference: 1234567890
A4: =Summary!A4 -> Period: 01/01/2024 to 31/12/2024
A7: SME Scheme
A8: Qualifying expenditure for the period: | B8: Check | C8: Period 1 | D8: Period 2 | E8: Total Spend | F8: Allowable | G8: Allowable Spend 1 | H8: Allowable Spend 2 | I8: Total Allowable | J8: Check
C9: =+Summary!$B$8 -> 45292 | D9: =+Summary!$B$9 -> 45383 | G9: =+Summary!$B$8 -> 45292 | H9: =+Summary!$B$9 -> 45383
C10: =+Summary!$C$8 -> 45382 | D10: =+Summary!$C$9 -> 45657 | G10: =+Summary!$C$8 -> 45382 | H10: =+Summary!$C$9 -> 45657
A11: UK staff costs | B11: =+E11-C11-D11 -> 0 | C11: =(SUMIFS(Staff!AO7:AO900,Staff!D7:D900,">="&C9,Staff!D7:D900,"<="&C10))+(SUMIFS(Staff!BE7:BE900,Staff!D7:D900,">="&C9,Staff!D7:D900,"<="&C10))-((Staff!AO919+Staff!BE919)/E25*E23) -> 153360.35 | D11: =(SUMIFS(Staff!AO7:AO900,Staff!D7:D900,">="&D9,Staff!D7:D900,"<="&D10))+(SUMIFS(Staff!BE7:BE900,Staff!D7:D900,">="&D9,Staff!D7:D900,"<="&D10))-((Staff!AO919+Staff!BE919)/E25*E24) -> 458187.13 | E11: =Staff!AO921+Staff!BE921 -> 611547.48 | F11: 1 | G11: =+C11*$F11 -> 153360.35 | H11: =+D11*$F11 -> 458187.13 | I11: =SUM(G11:H11) -> 611547.48 | J11: =+(E11*F11)-I11 -> 0
A12: Overseas Staff costs | B12: =+E12-C12-D12 -> 0 | C12: =(SUMIFS('Overseas Staff'!AL7:AL902,'Overseas Staff'!D7:D902,">="&C9,'Overseas Staff'!D7:D902,"<="&C10)) +(SUMIFS('Overseas Staff'!BB7:BB902,'Overseas Staff'!D7:D902,">="&C9,'Overseas Staff'!D7:D902,"<="&C10)) -> 0 | D12: =(SUMIFS('Overseas Staff'!AL7:AL902,'Overseas Staff'!D7:D902,">="&D9,'Overseas Staff'!D7:D902,"<="&D10)) +(SUMIFS('Overseas Staff'!BB7:BB902,'Overseas Staff'!D7:D902,">="&D9,'Overseas Staff'!D7:D902,"<="&D10)) -> 0 | E12: =+'Overseas Staff'!AL905+'Overseas Staff'!BB905 -> 0 | F12: 1 | G12: =+C12*$F12 -> 0 | H12: =+D12*$F12 -> 0 | I12: =SUM(G12:H12) -> 0 | J12: =+(E12*F12)-I12 -> 0
A13: Recruitment & relocation | B13: =+E13-C13-D13 -> 0 | C13: =SUMIFS('Recruitment & Relocation'!AK7:AK48, 'Recruitment & Relocation'!A7:A48, ">="&$C$9, 'Recruitment & Relocation'!A7:A48, "<="&$C$10) -> 10050 | D13: =SUMIFS('Recruitment & Relocation'!AK7:AK48, 'Recruitment & Relocation'!A7:A48, ">="&$D$9, 'Recruitment & Relocation'!A7:A48, "<="&$D$10) -> 4050 | E13: ='Recruitment & Relocation'!AK50 -> 14100 | F13: 0.65 | G13: =+C13*$F13 -> 6532.5 | H13: =+D13*$F13 -> 2632.5 | I13: =SUM(G13:H13) -> 9165 | J13: =+(E13*F13)-I13 -> 0
A14: Training | B14: =+E14-C14-D14 -> 0 | C14: =SUMIFS(Training!AI7:AI50,Training!A7:A50, ">="&$C$9,Training!A7:A50, "<="&$C$10) -> 2550 | D14: =SUMIFS(Training!AI7:AI50,Training!A7:A50, ">="&$D$9,Training!A7:A50, "<="&$D$10) -> 6100 | E14: =Training!AI52 -> 8650 | F14: 1 | G14: =+C14*$F14 -> 2550 | H14: =+D14*$F14 -> 6100 | I14: =SUM(G14:H14) -> 8650 | J14: =+(E14*F14)-I14 -> 0
A15: Travel & subsistence (Out of pocket expenses only) | B15: =+E15-C15-D15 -> 0 | C15: =SUMIFS('Travel & Subsistence'!AI7:AI99, 'Travel & Subsistence'!A7:A99, ">="&$C$9, 'Travel & Subsistence'!A7:A99, "<="&$C$10) -> 795 | D15: =SUMIFS('Travel & Subsistence'!AI7:AI99, 'Travel & Subsistence'!A7:A99, ">="&$D$9, 'Travel & Subsistence'!A7:A99, "<="&$D$10) -> 1827 | E15: ='Travel & Subsistence'!AI101 -> 2622 | F15: 1 | G15: =+C15*$F15 -> 795 | H15: =+D15*$F15 -> 1827 | I15: =SUM(G15:H15) -> 2622 | J15: =+(E15*F15)-I15 -> 0
A16: Software | B16: =+E16-C16-D16 -> 0 | C16: =SUMIFS(Software!AI7:AI245, Software!A7:A245, ">="&$C$9, Software!A7:A245, "<="&$C$10) -> 14080 | D16: =SUMIFS(Software!AI7:AI245, Software!A7:A245, ">="&$D$9, Software!A7:A245, "<="&$D$10) -> 24592 | E16: =Software!AI247 -> 38672 | F16: 1 | G16: =+C16*$F16 -> 14080 | H16: =+D16*$F16 -> 24592 | I16: =SUM(G16:H16) -> 38672 | J16: =+(E16*F16)-I16 -> 0
A17: Materials & consumables | B17: =+E17-C17-D17 -> 0 | C17: =(SUMIFS('Materials and Consumables'!AI7:AI211,'Materials and Consumables'!A7:A211,">="&$C$9,'Materials and Consumables'!A7:A211,"<="&$C$10))+(SUMIFS(Subcontractors!BF7:BF208,Subcontractors!A7:A208,">="&$C$9,Subcontractors!A7:A208,"<="&$C$10)) -> 17134 | D17: =(SUMIFS('Materials and Consumables'!AI7:AI211,'Materials and Consumables'!A7:A211,">="&$D$9,'Materials and Consumables'!A7:A211,"<="&$D$10))+(SUMIFS(Subcontractors!BF7:BF208,Subcontractors!A7:A208,">="&$D$9,Subcontractors!A7:A208,"<="&$D$10)) -> 24020 | E17: ='Materials and Consumables'!AI215+Subcontractors!BF210 -> 41154 | F17: 1 | G17: =+C17*$F17 -> 17134 | H17: =+D17*$F17 -> 24020 | I17: =SUM(G17:H17) -> 41154 | J17: =+(E17*F17)-I17 -> 0
A18: Subcontractors (Connected parties) | B18: =+E18-C18-D18 -> 0 | C18: =SUMIFS(Subcontractors!AO7:AO208, Subcontractors!A7:A208, ">="&$C$9, Subcontractors!A7:A208, "<="&$C$10) -> 0 | D18: =SUMIFS(Subcontractors!AO7:AO208, Subcontractors!A7:A208, ">="&$D$9, Subcontractors!A7:A208, "<="&$D$10) -> 0 | E18: =+Subcontractors!AO210 -> 0 | F18: 1 | G18: =+C18*$F18 -> 0 | H18: =+D18*$F18 -> 0 | I18: =SUM(G18:H18) -> 0 | J18: =+(E18*F18)-I18 -> 0
A19: Subcontractors (Unconnected parties) | B19: =+E19-C19-D19 -> 0 | C19: =SUMIFS(Subcontractors!AP7:AP208, Subcontractors!A7:A208, ">="&$C$9, Subcontractors!A7:A208, "<="&$C$10) -> 23476 | D19: =SUMIFS(Subcontractors!AP8:AP209, Subcontractors!A8:A209, ">="&$D$9, Subcontractors!A8:A209, "<="&$D$10) -> 44790 | E19: =+Subcontractors!AP210 -> 68266 | F19: 0.65 | G19: =+C19*$F19 -> 15259.4 | H19: =+D19*$F19 -> 29113.5 | I19: =SUM(G19:H19) -> 44372.9 | J19: =+(E19*F19)-I19 -> 0
A20: Total relevant net expenditure | B20: =SUM(B11:B19) -> 0 | C20: =SUM(C11:C19) -> 221445.35 | D20: =SUM(D11:D19) -> 563566.13 | E20: =SUM(E11:E19) -> 785011.48 | G20: =SUM(G11:G19) -> 209711.25 | H20: =SUM(H11:H19) -> 546472.13 | I20: =SUM(I11:I19) -> 756183.38 | J20: =SUM(J11:J19) -> 0
A22: Claim for enhancement:
A23: =(TEXT(C9,"MMM-YY")&" to "&(TEXT(C10,"mmm-yy"))) -> Jan-24 to Mar-24 | E23: =+Summary!D8 -> 3 | F23: 1.3 | G23: =+G20*F23 -> 272624.63 | H23: 0 | I23: =SUM(G23:H23) -> 272624.63
A24: =(TEXT(D9,"MMM-YY")&" to "&(TEXT(D10,"mmm-yy"))) -> Apr-24 to Dec-24 | E24: =+Summary!D9 -> 9 | F24: 0.86 | G24: 0 | H24: =+H20*F24 -> 469966.03 | I24: =SUM(G24:H24) -> 469966.03
A25: Total | E25: =SUM(E23:E24) -> 12 | G25: =SUM(G23:G24) -> 272624.63 | H25: =SUM(H23:H24) -> 469966.03 | I25: =SUM(I23:I24) -> 742590.66
A27: Surrendable tax credits:
A28: Normal taxable profit / (loss) on ordinary activities | G28: =+$I$28/$E$25*$E$23 -> -21250 | H28: =+$I$28/$E$25*$E$24 -> -63750 | I28: -85000 | J28: TBC
A29: Trading loss (after R&D relief) | G29: =IF((-G28+G25)>0,-G28+G25,0) -> 293874.63 | H29: =IF((-H28+H25)>0,-H28+H25,0) -> 533716.03 | I29: =IF((-I28+I25)>0,-I28+I25,0) -> 827590.66 | J29: A
A30: Total enhanced R&D spend | G30: =G20+G25 -> 482335.89 | H30: =H20+H25 -> 1016438.2 | I30: =I20+I25 -> 1498774 | J30: B
A31: Loss qualifying for conversion to repayable credits | G31: =IF(G29<G30,G29,G30) -> 293874.63 | H31: =IF(H29<H30,H29,H30) -> 533716.03 | I31: =IF(I29<I30,I29,I30) -> 827590.66 | J31: Lower of A or B
A33: SME intensive test:
A34: Total SME + RDEC R&D expenditure | I34: =+I20+I58 -> 915144.64
A35: Total trading & operating expenditure | I35: 1800000 | J35: TBC
A36: Intensitivity ratio | I36: =IFERROR(I34/I35, 0) -> 0.50841369
A38: Payable tax credit under SME scheme:
A39: =A23 -> Jan-24 to Mar-24 | F39: 0.145 | G39: =G31*F39 -> 42611.821 | H39: 0 | I39: =+G31*F39 -> 42611.821
A40: =A24 -> Apr-24 to Dec-24 | F40: 0.1 | G40: 0 | H40: =+H31*F40 -> 53371.603 | I40: =SUM(G40:H40) -> 53371.603
A41: =+A40 -> Apr-24 to Dec-24 | F41: 0.045 | G41: 0 | H41: =IF(I36>0.4,H31*F41, 0) -> 24017.221 | I41: =SUM(G41:H41) -> 24017.221
A42: Total payable SME tax credits | G42: =SUM(G39:G41) -> 42611.821 | H42: =SUM(H39:H41) -> 77388.824 | I42: =SUM(I39:I41) -> 120000.65
A46: RDEC Scheme
A47: Expenditure on R&D for which Innovate UK grants received: | B47: Check | C47: Period 1 | D47: Period 2 | E47: Spend | F47: Allowable % | G47: Allowable Spend 1 | H47: Allowable Spend 2 | I47: Total Allowable | J47: Check
C48: =+Summary!$B$8 -> 45292 | D48: =+Summary!$B$9 -> 45383 | G48: =+Summary!$B$8 -> 45292 | H48: =+Summary!$B$9 -> 45383
C49: =+Summary!$C$8 -> 45382 | D49: =+Summary!$C$9 -> 45657 | G49: =+Summary!$C$8 -> 45382 | H49: =+Summary!$C$9 -> 45657
...

Sheet Staff
A1: Staff Costs
L2: CLIENT INPUT | O2: CLIENT INPUT | AB2: DIRECT STAFF COSTS | AR2: INDIRECT STAFF COSTS | BJ2: ENGINEERS (Y / N)
B3: Name | C3: Position / Job Title | D3: Month | E3: Gross pay | F3: PAYE | G3: Employee's NI | H3: Employer's NI | I3: Employers Pension Contribution | J3: Total | L3: Direct % | M3: Indirect % | O3: =IF(Summary!$B$15>0,Summary!$B$15,"") -> Automated Document Intelligence Platform | P3: =IF(Summary!$B$16>0,Summary!$B$16,"") -> Real-Time Anomaly Detection Engine | Q3: =IF(Summary!$B$17>0,Summary!$B$17,"") -> Natural Language Query Interface | R3: =IF(Summary!$B$18>0,Summary!$B$18,"") -> Predictive Maintenance ML Pipeline | S3: =IF(Summary!$B$19>0,Summary!$B$19,"") -> Privacy-Preserving Data Linkage | T3: =IF(Summary!$B$20>0,Summary!$B$20,"") | U3: =IF(Summary!$B$21>0,Summary!$B$21,"") | V3: =IF(Summary!$B$22>0,Summary!$B$22,"") | W3: =IF(Summary!$B$23>0,Summary!$B$23,"") | X3: =IF(Summary!$B$24>0,Summary!$B$24,"") | Y3: =IF(Summary!$B$25>0,Summary!$B$25,"") | Z3: =IF(Summary!$B$26>0,Summary!$B$26,"") | AB3: =IF(Summary!$B$15>0,Summary!$B$15,"") -> Automated Document Intelligence Platform | AC3: =IF(Summary!$B$16>0,Summary!$B$16,"") -> Real-Time Anomaly Detection Engine | AD3: =IF(Summary!$B$17>0,Summary!$B$17,"") -> Natural Language Query Interface | AE3: =IF(Summary!$B$18>0,Summary!$B$18,"") -> Predictive Maintenance ML Pipeline | AF3: =IF(Summary!$B$19>0,Summary!$B$19,"") -> Privacy-Preserving Data Linkage | AG3: =IF(Summary!$B$20>0,Summary!$B$20,"") | AH3: =IF(Summary!$B$21>0,Summary!$B$21,"") | AI3: =IF(Summary!$B$22>0,Summary!$B$22,"") | AJ3: =IF(Summary!$B$23>0,Summary!$B$23,"") | AK3: =IF(Summary!$B$24>0,Summary!$B$24,"") | AL3: =IF(Summary!$B$25>0,Summary!$B$25,"") | AM3: =IF(Summary!$B$26>0,Summary!$B$26,"") | AN3: RDEC | AO3: SME | AP3: De Minimis | AR3: =IF(Summary!$B$15>0,Summary!$B$15,"") -> Automated Document Intelligence Platform | AS3: =IF(Summary!$B$16>0,Summary!$B$16,"") -> Real-Time Anomaly Detection Engine | AT3: =IF(Summary!$B$17>0,Summary!$B$17,"") -> Natural Language Query Interface | AU3: =IF(Summary!$B$18>0,Summary!$B$18,"") -> Predictive Maintenance ML Pipeline | AV3: =IF(Summary!$B$19>0,Summary!$B$19,"") -> Privacy-Preserving Data Linkage | AW3: =IF(Summary!$B$20>0,Summary!$B$20,"") | AX3: =IF(Summary!$B$21>0,Summary!$B$21,"") | AY3: =IF(Summary!$B$22>0,Summary!$B$22,"") | AZ3: =IF(Summary!$B$23>0,Summary!$B$23,"") | BA3: =IF(Summary!$B$24>0,Summary!$B$24,"") | BB3: =IF(Summary!$B$25>0,Summary!$B$25,"") | BC3: =IF(Summary!$B$26>0,Summary!$B$26,"") | BD3: RDEC | BE3: SME | BF3: De Minimis | BH3: Check | BJ3: Job Title | BK3: Engineer Y / N | BL3: Cost | BM3: RDEC | BN3: SME
O4: =IF(ISBLANK(Summary!$C$15),"", IF(Summary!$C$15="No", "SME", IF(AND(Summary!$C$15="Yes", Summary!$D$15="Yes"), "De Minimis", "RDEC"))) -> SME | P4: =IF(ISBLANK(Summary!$C$16),"", IF(Summary!$C$16="No", "SME", IF(AND(Summary!$C$16="Yes", Summary!$D$16="Yes"), "De Minimis", "RDEC"))) -> SME | Q4: =IF(ISBLANK(Summary!$C$17),"", IF(Summary!$C$17="No", "SME", IF(AND(Summary!$C$17="Yes", Summary!$D$17="Yes"), "De Minimis", "RDEC"))) -> SME | R4: =IF(ISBLANK(Summary!$C$18),"", IF(Summary!$C$18="No", "SME", IF(AND(Summary!$C$18="Yes", Summary!$D$18="Yes"), "De Minimis", "RDEC"))) -> RDEC | S4: =IF(ISBLANK(Summary!$C$19),"", IF(Summary!$C$19="No", "SME", IF(AND(Summary!$C$19="Yes", Summary!$D$19="Yes"), "De Minimis", "RDEC"))) -> SME | T4: =IF(ISBLANK(Summary!$C$20),"", IF(Summary!$C$20="No", "SME", IF(AND(Summary!$C$20="Yes", Summary!$D$20="Yes"), "De Minimis", "RDEC"))) | U4: =IF(ISBLANK(Summary!$C$21),"", IF(Summary!$C$21="No", "SME", IF(AND(Summary!$C$21="Yes", Summary!$D$21="Yes"), "De Minimis", "RDEC"))) | V4: =IF(ISBLANK(Summary!$C$22),"", IF(Summary!$C$22="No", "SME", IF(AND(Summary!$C$22="Yes", Summary!$D$22="Yes"), "De Minimis", "RDEC"))) | W4: =IF(ISBLANK(Summary!$C$23),"", IF(Summary!$C$23="No", "SME", IF(AND(Summary!$C$23="Yes", Summary!$D$23="Yes"), "De Minimis", "RDEC"))) | X4: =IF(ISBLANK(Summary!$C$24),"", IF(Summary!$C$24="No", "SME", IF(AND(Summary!$C$24="Yes", Summary!$D$24="Yes"), "De Minimis", "RDEC"))) | Y4: =IF(ISBLANK(Summary!$C$25),"", IF(Summary!$C$25="No", "SME", IF(AND(Summary!$C$25="Yes", Summary!$D$25="Yes"), "De Minimis", "RDEC"))) | Z4: =IF(ISBLANK(Summary!$C$26),"", IF(Summary!$C$26="No", "SME", IF(AND(Summary!$C$26="Yes", Summary!$D$26="Yes"), "De Minimis", "RDEC"))) | AB4: =IF(ISBLANK(Summary!$C$15),"", IF(Summary!$C$15="No", "SME", IF(AND(Summary!$C$15="Yes", Summary!$D$15="Yes"), "De Minimis", "RDEC"))) -> SME | AC4: =IF(ISBLANK(Summary!$C$16),"", IF(Summary!$C$16="No", "SME", IF(AND(Summary!$C$16="Yes", Summary!$D$16="Yes"), "De Minimis", "RDEC"))) -> SME | AD4: =IF(ISBLANK(Summary!$C$17),"", IF(Summary!$C$17="No", "SME", IF(AND(Summary!$C$17="Yes", Summary!$D$17="Yes"), "De Minimis", "RDEC"))) -> SME | AE4: =IF(ISBLANK(Summary!$C$18),"", IF(Summary!$C$18="No", "SME", IF(AND(Summary!$C$18="Yes", Summary!$D$18="Yes"), "De Minimis", "RDEC"))) -> RDEC | AF4: =IF(ISBLANK(Summary!$C$19),"", IF(Summary!$C$19="No", "SME", IF(AND(Summary!$C$19="Yes", Summary!$D$19="Yes"), "De Minimis", "RDEC"))) -> SME | AG4: =IF(ISBLANK(Summary!$C$20),"", IF(Summary!$C$20="No", "SME", IF(AND(Summary!$C$20="Yes", Summary!$D$20="Yes"), "De Minimis", "RDEC"))) | AH4: =IF(ISBLANK(Summary!$C$21),"", IF(Summary!$C$21="No", "SME", IF(AND(Summary!$C$21="Yes", Summary!$D$21="Yes"), "De Minimis", "RDEC"))) | AI4: =IF(ISBLANK(Summary!$C$22),"", IF(Summary!$C$22="No", "SME", IF(AND(Summary!$C$22="Yes", Summary!$D$22="Yes"), "De Minimis", "RDEC"))) | AJ4: =IF(ISBLANK(Summary!$C$23),"", IF(Summary!$C$23="No", "SME", IF(AND(Summary!$C$23="Yes", Summary!$D$23="Yes"), "De Minimis", "RDEC"))) | AK4: =IF(ISBLANK(Summary!$C$24),"", IF(Summary!$C$24="No", "SME", IF(AND(Summary!$C$24="Yes", Summary!$D$24="Yes"), "De Minimis", "RDEC"))) | AL4: =IF(ISBLANK(Summary!$C$25),"", IF(Summary!$C$25="No", "SME", IF(AND(Summary!$C$25="Yes", Summary!$D$25="Yes"), "De Minimis", "RDEC"))) | AM4: =IF(ISBLANK(Summary!$C$26),"", IF(Summary!$C$26="No", "SME", IF(AND(Summary!$C$26="Yes", Summary!$D$26="Yes"), "De Minimis", "RDEC"))) | AR4: =IF(ISBLANK(Summary!$C$15),"", IF(Summary!$C$15="No", "SME", IF(AND(Summary!$C$15="Yes", Summary!$D$15="Yes"), "De Minimis", "RDEC"))) -> SME | AS4: =IF(ISBLANK(Summary!$C$16),"", IF(Summary!$C$16="No", "SME", IF(AND(Summary!$C$16="Yes", Summary!$D$16="Yes"), "De Minimis", "RDEC"))) -> SME | AT4: =IF(ISBLANK(Summary!$C$17),"", IF(Summary!$C$17="No", "SME", IF(AND(Summary!$C$17="Yes", Summary!$D$17="Yes"), "De Minimis", "RDEC"))) -> SME | AU4: =IF(ISBLANK(Summary!$C$18),"", IF(Summary!$C$18="No", "SME", IF(AND(Summary!$C$18="Yes", Summary!$D$18="Yes"), "De Minimis", "RDEC"))) -> RDEC | AV4: =IF(ISBLANK(Summary!$C$19),"", IF(Summary!$C$19="No", "SME", IF(AND(Summary!$C$19="Yes", Summary!$D$19="Yes"), "De Minimis", "RDEC"))) -> SME | AW4: =IF(ISBLANK(Summary!$C$20),"", IF(Summary!$C$20="No", "SME", IF(AND(Summary!$C$20="Yes", Summary!$D$20="Yes"), "De Minimis", "RDEC"))) | AX4: =IF(ISBLANK(Summary!$C$21),"", IF(Summary!$C$21="No", "SME", IF(AND(Summary!$C$21="Yes", Summary!$D$21="Yes"), "De Minimis", "RDEC"))) | AY4: =IF(ISBLANK(Summary!$C$22),"", IF(Summary!$C$22="No", "SME", IF(AND(Summary!$C$22="Yes", Summary!$D$22="Yes"), "De Minimis", "RDEC"))) | AZ4: =IF(ISBLANK(Summary!$C$23),"", IF(Summary!$C$23="No", "SME", IF(AND(Summary!$C$23="Yes", Summary!$D$23="Yes"), "De Minimis", "RDEC"))) | BA4: =IF(ISBLANK(Summary!$C$24),"", IF(Summary!$C$24="No", "SME", IF(AND(Summary!$C$24="Yes", Summary!$D$24="Yes"), "De Minimis", "RDEC"))) | BB4: =IF(ISBLANK(Summary!$C$25),"", IF(Summary!$C$25="No", "SME", IF(AND(Summary!$C$25="Yes", Summary!$D$25="Yes"), "De Minimis", "RDEC"))) | BC4: =IF(ISBLANK(Summary!$C$26),"", IF(Summary!$C$26="No", "SME", IF(AND(Summary!$C$26="Yes", Summary!$D$26="Yes"), "De Minimis", "RDEC")))
O5: R&D % | P5: R&D % | Q5: R&D % | R5: R&D % | S5: R&D % | T5: R&D % | U5: R&D % | V5: R&D % | W5: R&D % | X5: R&D % | Y5: R&D % | Z5: R&D % | AB5: R&D £ | AC5: R&D £ | AD5: R&D £ | AE5: R&D £ | AF5: R&D £ | AG5: R&D £ | AH5: R&D £ | AI5: R&D £ | AJ5: R&D £ | AK5: R&D £ | AL5: R&D £ | AM5: R&D £ | AN5: R&D £ | AO5: R&D £ | AP5: R&D £ | AR5: R&D £ | AS5: R&D £ | AT5: R&D £ | AU5: R&D £ | AV5: R&D £ | AW5: R&D £ | AX5: R&D £ | AY5: R&D £ | AZ5: R&D £ | BA5: R&D £ | BB5: R&D £ | BC5: R&D £ | BD5: R&D £ | BE5: R&D £ | BF5: R&D £ | BH5: %
A6: 1 | B6: James Harrison | C6: Chief Technology Officer
D8: =+Summary!B8 -> 45292 | E8: 8025.74 | F8: 2648.49 | G8: 581.39 | H8: 1002.9 | I8: 401.29 | J8: =E8+H8+I8 -> 9429.93 | L8: 0.6 | M8: =1-L8 -> 0.4 | O8: 0.3 | P8: 0.25 | Q8: 0.15 | R8: 0.2 | S8: 0.1 | AB8: =IFERROR(($J8*O8)*$L8, "") -> 1697.3874 | AC8: =IFERROR(($J8*P8)*$L8, "") -> 1414.4895 | AD8: =IFERROR(($J8*Q8)*$L8, "") -> 848.6937 | AE8: =IFERROR(($J8*R8)*$L8, "") -> 1131.5916 | AF8: =IFERROR(($J8*S8)*$L8, "") -> 565.7958 | AG8: =IFERROR(($J8*T8)*$L8, "") -> 0 | AH8: =IFERROR(($J8*U8)*$L8, "") -> 0 | AI8: =IFERROR(($J8*V8)*$L8, "") -> 0 | ... AM8: =IFERROR(($J8*Z8)*$L8, "") -> 0 | AN8: =IFERROR(SUMIF($AB$4:$AM$4, "RDEC", AB8:AM8), "") -> 1131.5916 | AO8: =IFERROR(SUMIF($AB$4:$AM$4, "SME", AB8:AM8), "") -> 4526.3664 | AP8: =IFERROR(SUMIF($AB$4:$AM$4, "De Minimis", AB8:AM8), "") -> 0 | AR8: =IFERROR(($J8*O8)*$M8, "") -> 1131.5916 | AS8: =IFERROR(($J8*P8)*$M8, "") -> 942.993 | AT8: =IFERROR(($J8*Q8)*$M8, "") -> 565.7958 | AU8: =IFERROR(($J8*R8)*$M8, "") -> 754.3944 | AV8: =IFERROR(($J8*S8)*$M8, "") -> 377.1972 | AW8: =IFERROR(($J8*T8)*$M8, "") -> 0 | AX8: =IFERROR(($J8*U8)*$M8, "") -> 0 | AY8: =IFERROR(($J8*V8)*$M8, "") -> 0 | ... BC8: =IFERROR(($J8*Z8)*$M8, "") -> 0 | BD8: =IFERROR(SUMIF($AB$4:$AM$4, "RDEC", AR8:BC8), "") -> 754.3944 | BE8: =IFERROR(SUMIF($AB$4:$AM$4, "SME", AR8:BC8), "") -> 3017.5776 | BF8: =IFERROR(SUMIF($AB$4:$AM$4, "De Minimis", AR8:BC8), "") -> 0 | BH8: =IF((SUM(O8:Z8)>1),"ERROR","")
D9: =+EDATE(D8, 1) -> 45323 | E9: 7800.89 | F9: 2574.29 | G9: 563.4 | H9: 971.87 | I9: 390.04 | J9: =E9+H9+I9 -> 9162.8 | L9: 0.6 | M9: =1-L9 -> 0.4 | O9: 0.3 | P9: 0.25 | Q9: 0.15 | R9: 0.2 | S9: 0.1 | AB9: =IFERROR(($J9*O9)*$L9, "") -> 1649.304 | AC9: =IFERROR(($J9*P9)*$L9, "") -> 1374.42 | AD9: =IFERROR(($J9*Q9)*$L9, "") -> 824.652 | AE9: =IFERROR(($J9*R9)*$L9, "") -> 1099.536 | AF9: =IFERROR(($J9*S9)*$L9, "") -> 549.768 | AG9: =IFERROR(($J9*T9)*$L9, "") -> 0 | AH9: =IFERROR(($J9*U9)*$L9, "") -> 0 | AI9: =IFERROR(($J9*V9)*$L9, "") -> 0 | ... AM9: =IFERROR(($J9*Z9)*$L9, "") -> 0 | AN9: =IFERROR(SUMIF($AB$4:$AM$4, "RDEC", AB9:AM9), "") -> 1099.536 | AO9: =IFERROR(SUMIF($AB$4:$AM$4, "SME", AB9:AM9), "") -> 4398.144 | AP9: =IFERROR(SUMIF($AB$4:$AM$4, "De Minimis", AB9:AM9), "") -> 0 | AR9: =IFERROR(($J9*O9)*$M9, "") -> 1099.536 | AS9: =IFERROR(($J9*P9)*$M9, "") -> 916.28 | AT9: =IFERROR(($J9*Q9)*$M9, "") -> 549.768 | AU9: =IFERROR(($J9*R9)*$M9, "") -> 733.024 | AV9: =IFERROR(($J9*S9)*$M9, "") -> 366.512 | AW9: =IFERROR(($J9*T9)*$M9, "") -> 0 | AX9: =IFERROR(($J9*U9)*$M9, "") -> 0 | AY9: =IFERROR(($J9*V9)*$M9, "") -> 0 | ... BC9: =IFERROR(($J9*Z9)*$M9, "") -> 0 | BD9: =IFERROR(SUMIF($AB$4:$AM$4, "RDEC", AR9:BC9), "") -> 733.024 | BE9: =IFERROR(SUMIF($AB$4:$AM$4, "SME", AR9:BC9), "") -> 2932.096 | BF9: =IFERROR(SUMIF($AB$4:$AM$4, "De Minimis", AR9:BC9), "") -> 0 | BH9: =IF((SUM(O9:Z9)>1),"ERROR","")
D10: =+EDATE(D9, 1) -> 45352 | E10: 8061.08 | F10: 2660.16 | G10: 584.22 | H10: 1007.78 | I10: 403.05 | J10: =E10+H10+I10 -> 9471.91 | L10: 0.6 | M10: =1-L10 -> 0.4 | O10: 0.3 | P10: 0.25 | Q10: 0.15 | R10: 0.2 | S10: 0.1 | AB10: =IFERROR(($J10*O10)*$L10, "") -> 1704.9438 | AC10: =IFERROR(($J10*P10)*$L10, "") -> 1420.7865 | AD10: =IFERROR(($J10*Q10)*$L10, "") -> 852.4719 | AE10: =IFERROR(($J10*R10)*$L10, "") -> 1136.6292 | AF10: =IFERROR(($J10*S10)*$L10, "") -> 568.3146 | AG10: =IFERROR(($J10*T10)*$L10, "") -> 0 | AH10: =IFERROR(($J10*U10)*$L10, "") -> 0 | AI10: =IFERROR(($J10*V10)*$L10, "") -> 0 | ... AM10: =IFERROR(($J10*Z10)*$L10, "") -> 0 | AN10: =IFERROR(SUMIF($AB$4:$AM$4, "RDEC", AB10:AM10), "") -> 1136.6292 | AO10: =IFERROR(SUMIF($AB$4:$AM$4, "SME", AB10:AM10), "") -> 4546.5168 | AP10: =IFERROR(SUMIF($AB$4:$AM$4, "De Minimis", AB10:AM10), "") -> 0 | AR10: =IFERROR(($J10*O10)*$M10, "") -> 1136.6292 | AS10: =IFERROR(($J10*P10)*$M10, "") -> 947.191 | AT10: =IFERROR(($J10*Q10)*$M10, "") -> 568.3146 | AU10: =IFERROR(($J10*R10)*$M10, "") -> 757.7528 | AV10: =IFERROR(($J10*S10)*$M10, "") -> 378.8764 | AW10: =IFERROR(($J10*T10)*$M10, "") -> 0 | AX10: =IFERROR(($J10*U10)*$M10, "") -> 0 | AY10: =IFERROR(($J10*V10)*$M10, "") -> 0 | ... BC10: =IFERROR(($J10*Z10)*$M10, "") -> 0 | BD10: =IFERROR(SUMIF($AB$4:$AM$4, "RDEC", AR10:BC10), "") -> 757.7528 | BE10: =IFERROR(SUMIF($AB$4:$AM$4, "SME", AR10:BC10), "") -> 3031.0112 | BF10: =IFERROR(SUMIF($AB$4:$AM$4, "De Minimis", AR10:BC10), "") -> 0 | BH10: =IF((SUM(O10:Z10)>1),"ERROR","")
D11: =+EDATE(D10, 1) -> 45383 | E11: 7833.69 | F11: 2585.12 | G11: 566.03 | H11: 976.4 | I11: 391.68 | J11: =E11+H11+I11 -> 9201.77 | L11: 0.6 | M11: =1-L11 -> 0.4 | O11: 0.3 | P11: 0.25 | Q11: 0.15 | R11: 0.2 | S11: 0.1 | AB11: =IFERROR(($J11*O11)*$L11, "") -> 1656.3186 | AC11: =IFERROR(($J11*P11)*$L11, "") -> 1380.2655 | AD11: =IFERROR(($J11*Q11)*$L11, "") -> 828.1593 | AE11: =IFERROR(($J11*R11)*$L11, "") -> 1104.2124 | AF11: =IFERROR(($J11*S11)*$L11, "") -> 552.1062 | AG11: =IFERROR(($J11*T11)*$L11, "") -> 0 | AH11: =IFERROR(($J11*U11)*$L11, "") -> 0 | AI11: =IFERROR(($J11*V11)*$L11, "") -> 0 | ... AM11: =IFERROR(($J11*Z11)*$L11, "") -> 0 | AN11: =IFERROR(SUMIF($AB$4:$AM$4, "RDEC", AB11:AM11), "") -> 1104.2124 | AO11: =IFERROR(SUMIF($AB$4:$AM$4, "SME", AB11:AM11), "") -> 4416.8496 | AP11: =IFERROR(SUMIF($AB$4:$AM$4, "De Minimis", AB11:AM11), "") -> 0 | AR11: =IFERROR(($J11*O11)*$M11, "") -> 1104.2124 | AS11: =IFERROR(($J11*P11)*$M11, "") -> 920.177 | AT11: =IFERROR(($J11*Q11)*$M11, "") -> 552.1062 | AU11: =IFERROR(($J11*R11)*$M11, "") -> 736.1416 | AV11: =IFERROR(($J11*S11)*$M11, "") -> 368.0708 | AW11: =IFERROR(($J11*T11)*$M11, "") -> 0 | AX11: =IFERROR(($J11*U11)*$M11, "") -> 0 | AY11: =IFERROR(($J11*V11)*$M11, "") -> 0 | ... BC11: =IFERROR(($J11*Z11)*$M11, "") -> 0 | BD11: =IFERROR(SUMIF($AB$4:$AM$4, "RDEC", AR11:BC11), "") -> 736.1416 | BE11: =IFERROR(SUMIF($AB$4:$AM$4, "SME", AR11:BC11), "") -> 2944.5664 | BF11: =IFERROR(SUMIF($AB$4:$AM$4, "De Minimis", AR11:BC11), "") -> 0 | BH11: =IF((SUM(O11:Z11)>1),"ERROR","")
D12: =+EDATE(D11, 1) -> 45413 | E12: 7833.09 | F12: 2584.92 | G12: 565.98 | H12: 976.32 | I12: 391.65 | J12: =E12+H12+I12 -> 9201.06 | L12: 0.6 | M12: =1-L12 -> 0.4 | O12: 0.3 | P12: 0.25 | Q12: 0.15 | R12: 0.2 | S12: 0.1 | AB12: =IFERROR(($J12*O12)*$L12, "") -> 1656.1908 | AC12: =IFERROR(($J12*P12)*$L12, "") -> 1380.159 | AD12: =IFERROR(($J12*Q12)*$L12, "") -> 828.0954 | AE12: =IFERROR(($J12*R12)*$L12, "") -> 1104.1272 | AF12: =IFERROR(($J12*S12)*$L12, "") -> 552.0636 | AG12: =IFERROR(($J12*T12)*$L12, "") -> 0 | AH12: =IFERROR(($J12*U12)*$L12, "") -> 0 | AI12: =IFERROR(($J12*V12)*$L12, "") -> 0 | ... AM12: =IFERROR(($J12*Z12)*$L12, "") -> 0 | AN12: =IFERROR(SUMIF($AB$4:$AM$4, "RDEC", AB12:AM12), "") -> 1104.1272 | AO12: =IFERROR(SUMIF($AB$4:$AM$4, "SME", AB12:AM12), "") -> 4416.5088 | AP12: =IFERROR(SUMIF($AB$4:$AM$4, "De Minimis", AB12:AM12), "") -> 0 | AR12: =IFERROR(($J12*O12)*$M12, "") -> 1104.1272 | AS12: =IFERROR(($J12*P12)*$M12, "") -> 920.106 | AT12: =IFERROR(($J12*Q12)*$M12, "") -> 552.0636 | AU12: =IFERROR(($J12*R12)*$M12, "") -> 736.0848 | AV12: =IFERROR(($J12*S12)*$M12, "") -> 368.0424 | AW12: =IFERROR(($J12*T12)*$M12, "") -> 0 | AX12: =IFERROR(($J12*U12)*$M12, "") -> 0 | AY12: =IFERROR(($J12*V12)*$M12, "") -> 0 | ... BC12: =IFERROR(($J12*Z12)*$M12, "") -> 0 | BD12: =IFERROR(SUMIF($AB$4:$AM$4, "RDEC", AR12:BC12), "") -> 736.0848 | BE12: =IFERROR(SUMIF($AB$4:$AM$4, "SME", AR12:BC12), "") -> 2944.3392 | BF12: =IFERROR(SUMIF($AB$4:$AM$4, "De Minimis", AR12:BC12), "") -> 0 | BH12: =IF((SUM(O12:Z12)>1),"ERROR","")
D13: =+EDATE(D12, 1) -> 45444 | E13: 7955.59 | F13: 2625.34 | G13: 575.78 | H13: 993.22 | I13: 397.78 | J13: =E13+H13+I13 -> 9346.59 | L13: 0.6 | M13: =1-L13 -> 0.4 | O13: 0.3 | P13: 0.25 | Q13: 0.15 | R13: 0.2 | S13: 0.1 | AB13: =IFERROR(($J13*O13)*$L13, "") -> 1682.3862 | AC13: =IFERROR(($J13*P13)*$L13, "") -> 1401.9885 | AD13: =IFERROR(($J13*Q13)*$L13, "") -> 841.1931 | AE13: =IFERROR(($J13*R13)*$L13, "") -> 1121.5908 | AF13: =IFERROR(($J13*S13)*$L13, "") -> 560.7954 | AG13: =IFERROR(($J13*T13)*$L13, "") -> 0 | AH13: =IFERROR(($J13*U13)*$L13, "") -> 0 | AI13: =IFERROR(($J13*V13)*$L13, "") -> 0 | ... AM13: =IFERROR(($J13*Z13)*$L13, "") -> 0 | AN13: =IFERROR(SUMIF($AB$4:$AM$4, "RDEC", AB13:AM13), "") -> 1121.5908 | AO13: =IFERROR(SUMIF($AB$4:$AM$4, "SME", AB13:AM13), "") -> 4486.3632 | AP13: =IFERROR(SUMIF($AB$4:$AM$4, "De Minimis", AB13:AM13), "") -> 0 | AR13: =IFERROR(($J13*O13)*$M13, "") -> 1121.5908 | AS13: =IFERROR(($J13*P13)*$M13, "") -> 934.659 | AT13: =IFERROR(($J13*Q13)*$M13, "") -> 560.7954 | AU13: =IFERROR(($J13*R13)*$M13, "") -> 747.7272 | AV13: =IFERROR(($J13*S13)*$M13, "") -> 373.8636 | AW13: =IFERROR(($J13*T13)*$M13, "") -> 0 | AX13: =IFERROR(($J13*U13)*$M13, "") -> 0 | AY13: =IFERROR(($J13*V13)*$M13, "") -> 0 | ... BC13: =IFERROR(($J13*Z13)*$M13, "") -> 0 | BD13: =IFERROR(SUMIF($AB$4:$AM$4, "RDEC", AR13:BC13), "") -> 747.7272 | BE13: =IFERROR(SUMIF($AB$4:$AM$4, "SME", AR13:BC13), "") -> 2990.9088 | BF13: =IFERROR(SUMIF($AB$4:$AM$4, "De Minimis", AR13:BC13), "") -> 0 | BH13: =IF((SUM(O13:Z13)>1),"ERROR","")
D14: =+EDATE(D13, 1) -> 45474 | E14: 8009.56 | F14: 2643.15 | G14: 580.1 | H14: 1000.67 | I14: 400.48 | J14: =E14+H14+I14 -> 9410.71 | L14: 0.6 | M14: =1-L14 -> 0.4 | O14: 0.3 | P14: 0.25 | Q14: 0.15 | R14: 0.2 | S14: 0.1 | AB14: =IFERROR(($J14*O14)*$L14, "") -> 1693.9278 | AC14: =IFERROR(($J14*P14)*$L14, "") -> 1411.6065 | AD14: =IFERROR(($J14*Q14)*$L14, "") -> 846.9639 | AE14: =IFERROR(($J14*R14)*$L14, "") -> 1129.2852 | AF14: =IFERROR(($J14*S14)*$L14, "") -> 564.6426 | AG14: =IFERROR(($J14*T14)*$L14, "") -> 0 | AH14: =IFERROR(($J14*U14)*$L14, "") -> 0 | AI14: =IFERROR(($J14*V14)*$L14, "") -> 0 | ... AM14: =IFERROR(($J14*Z14)*$L14, "") -> 0 | AN14: =IFERROR(SUMIF($AB$4:$AM$4, "RDEC", AB14:AM14), "") -> 1129.2852 | AO14: =IFERROR(SUMIF($AB$4:$AM$4, "SME", AB14:AM14), "") -> 4517.1408 | AP14: =IFERROR(SUMIF($AB$4:$AM$4, "De Minimis", AB14:AM14), "") -> 0 | AR14: =IFERROR(($J14*O14)*$M14, "") -> 1129.2852 | AS14: =IFERROR(($J14*P14)*$M14, "") -> 941.071 | AT14: =IFERROR(($J14*Q14)*$M14, "") -> 564.6426 | AU14: =IFERROR(($J14*R14)*$M14, "") -> 752.8568 | AV14: =IFERROR(($J14*S14)*$M14, "") -> 376.4284 | AW14: =IFERROR(($J14*T14)*$M14, "") -> 0 | AX14: =IFERROR(($J14*U14)*$M14, "") -> 0 | AY14: =IFERROR(($J14*V14)*$M14, "") -> 0 | ... BC14: =IFERROR(($J14*Z14)*$M14, "") -> 0 | BD14: =IFERROR(SUMIF($AB$4:$AM$4, "RDEC", AR14:BC14), "") -> 752.8568 | BE14: =IFERROR(SUMIF($AB$4:$AM$4, "SME", AR14:BC14), "") -> 3011.4272 | BF14: =IFERROR(SUMIF($AB$4:$AM$4, "De Minimis", AR14:BC14), "") -> 0 | BH14: =IF((SUM(O14:Z14)>1),"ERROR","")
D15: =+EDATE(D14, 1) -> 45505 | E15: 7860.88 | F15: 2594.09 | G15: 568.2 | H15: 980.15 | I15: 393.04 | J15: =E15+H15+I15 -> 9234.07 | L15: 0.6 | M15: =1-L15 -> 0.4 | O15: 0.3 | P15: 0.25 | Q15: 0.15 | R15: 0.2 | S15: 0.1 | AB15: =IFERROR(($J15*O15)*$L15, "") -> 1662.1326 | AC15: =IFERROR(($J15*P15)*$L15, "") -> 1385.1105 | AD15: =IFERROR(($J15*Q15)*$L15, "") -> 831.0663 | AE15: =IFERROR(($J15*R15)*$L15, "") -> 1108.0884 | AF15: =IFERROR(($J15*S15)*$L15, "") -> 554.0442 | AG15: =IFERROR(($J15*T15)*$L15, "") -> 0 | AH15: =IFERROR(($J15*U15)*$L15, "") -> 0 | AI15: =IFERROR(($J15*V15)*$L15, "") -> 0 | ... AM15: =IFERROR(($J15*Z15)*$L15, "") -> 0 | AN15: =IFERROR(SUMIF($AB$4:$AM$4, "RDEC", AB15:AM15), "") -> 1108.0884 | AO15: =IFERROR(SUMIF($AB$4:$AM$4, "SME", AB15:AM15), "") -> 4432.3536 | AP15: =IFERROR(SUMIF($AB$4:$AM$4, "De Minimis", AB15:AM15), "") -> 0 | AR15: =IFERROR(($J15*O15)*$M15, "") -> 1108.0884 | AS15: =IFERROR(($J15*P15)*$M15, "") -> 923.407 | AT15: =IFERROR(($J15*Q15)*$M15, "") -> 554.0442 | AU15: =IFERROR(($J15*R15)*$M15, "") -> 738.7256 | AV15: =IFERROR(($J15*S15)*$M15, "") -> 369.3628 | AW15: =IFERROR(($J15*T15)*$M15, "") -> 0 | AX15: =IFERROR(($J15*U15)*$M15, "") -> 0 | AY15: =IFERROR(($J15*V15)*$M15, "") -> 0 | ... BC15: =IFERROR(($J15*Z15)*$M15, "") -> 0 | BD15: =IFERROR(SUMIF($AB$4:$AM$4, "RDEC", AR15:BC15), "") -> 738.7256 | BE15: =IFERROR(SUMIF($AB$4:$AM$4, "SME", AR15:BC15), "") -> 2954.9024 | BF15: =IFERROR(SUMIF($AB$4:$AM$4, "De Minimis", AR15:BC15), "") -> 0 | BH15: =IF((SUM(O15:Z15)>1),"ERROR","")
D16: =+EDATE(D15, 1) -> 45536 | E16: 7830.13 | F16: 2583.94 | G16: 565.74 | H16: 975.91 | I16: 391.51 | J16: =E16+H16+I16 -> 9197.55 | L16: 0.6 | M16: =1-L16 -> 0.4 | O16: 0.3 | P16: 0.25 | Q16: 0.15 | R16: 0.2 | S16: 0.1 | AB16: =IFERROR(($J16*O16)*$L16, "") -> 1655.559 | AC16: =IFERROR(($J16*P16)*$L16, "") -> 1379.6325 | AD16: =IFERROR(($J16*Q16)*$L16, "") -> 827.7795 | AE16: =IFERROR(($J16*R16)*$L16, "") -> 1103.706 | AF16: =IFERROR(($J16*S16)*$L16, "") -> 551.853 | AG16: =IFERROR(($J16*T16)*$L16, "") -> 0 | AH16: =IFERROR(($J16*U16)*$L16, "") -> 0 | AI16: =IFERROR(($J16*V16)*$L16, "") -> 0 | ... AM16: =IFERROR(($J16*Z16)*$L16, "") -> 0 | AN16: =IFERROR(SUMIF($AB$4:$AM$4, "RDEC", AB16:AM16), "") -> 1103.706 | AO16: =IFERROR(SUMIF($AB$4:$AM$4, "SME", AB16:AM16), "") -> 4414.824 | AP16: =IFERROR(SUMIF($AB$4:$AM$4, "De Minimis", AB16:AM16), "") -> 0 | AR16: =IFERROR(($J16*O16)*$M16, "") -> 1103.706 | AS16: =IFERROR(($J16*P16)*$M16, "") -> 919.755 | AT16: =IFERROR(($J16*Q16)*$M16, "") -> 551.853 | AU16: =IFERROR(($J16*R16)*$M16, "") -> 735.804 | AV16: =IFERROR(($J16*S16)*$M16, "") -> 367.902 | AW16: =IFERROR(($J16*T16)*$M16, "") -> 0 | AX16: =IFERROR(($J16*U16)*$M16, "") -> 0 | AY16: =IFERROR(($J16*V16)*$M16, "") -> 0 | ... BC16: =IFERROR(($J16*Z16)*$M16, "") -> 0 | BD16: =IFERROR(SUMIF($AB$4:$AM$4, "RDEC", AR16:BC16), "") -> 735.804 | BE16: =IFERROR(SUMIF($AB$4:$AM$4, "SME", AR16:BC16), "") -> 2943.216 | BF16: =IFERROR(SUMIF($AB$4:$AM$4, "De Minimis", AR16:BC16), "") -> 0 | BH16: =IF((SUM(O16:Z16)>1),"ERROR","")
D17: =+EDATE(D16, 1) -> 45566 | E17: 7904.96 | F17: 2608.64 | G17: 571.73 | H17: 986.23 | I17: 395.25 | J17: =E17+H17+I17 -> 9286.44 | L17: 0.6 | M17: =1-L17 -> 0.4 | O17: 0.3 | P17: 0.25 | Q17: 0.15 | R17: 0.2 | S17: 0.1 | AB17: =IFERROR(($J17*O17)*$L17, "") -> 1671.5592 | AC17: =IFERROR(($J17*P17)*$L17, "") -> 1392.966 | AD17: =IFERROR(($J17*Q17)*$L17, "") -> 835.7796 | AE17: =IFERROR(($J17*R17)*$L17, "") -> 1114.3728 | AF17: =IFERROR(($J17*S17)*$L17, "") -> 557.1864 | AG17: =IFERROR(($J17*T17)*$L17, "") -> 0 | AH17: =IFERROR(($J17*U17)*$L17, "") -> 0 | AI17: =IFERROR(($J17*V17)*$L17, "") -> 0 | ... AM17: =IFERROR(($J17*Z17)*$L17, "") -> 0 | AN17: =IFERROR(SUMIF($AB$4:$AM$4, "RDEC", AB17:AM17), "") -> 1114.3728 | AO17: =IFERROR(SUMIF($AB$4:$AM$4, "SME", AB17:AM17), "") -> 4457.4912 | AP17: =IFERROR(SUMIF($AB$4:$AM$4, "De Minimis", AB17:AM17), "") -> 0 | AR17: =IFERROR(($J17*O17)*$M17, "") -> 1114.3728 | AS17: =IFERROR(($J17*P17)*$M17, "") -> 928.644 | AT17: =IFERROR(($J17*Q17)*$M17, "") -> 557.1864 | AU17: =IFERROR(($J17*R17)*$M17, "") -> 742.9152 | AV17: =IFERROR(($J17*S17)*$M17, "") -> 371.4576 | AW17: =IFERROR(($J17*T17)*$M17, "") -> 0 | AX17: =IFERROR(($J17*U17)*$M17, "") -> 0 | AY17: =IFERROR(($J17*V17)*$M17, "") -> 0 | ... BC17: =IFERROR(($J17*Z17)*$M17, "") -> 0 | BD17: =IFERROR(SUMIF($AB$4:$AM$4, "RDEC", AR17:BC17), "") -> 742.9152 | BE17: =IFERROR(SUMIF($AB$4:$AM$4, "SME", AR17:BC17), "") -> 2971.6608 | BF17: =IFERROR(SUMIF($AB$4:$AM$4, "De Minimis", AR17:BC17), "") -> 0 | BH17: =IF((SUM(O17:Z17)>1),"ERROR","")
D18: =+EDATE(D17, 1) -> 45597 | E18: 7939.28 | F18: 2619.96 | G18: 574.48 | H18: 990.97 | I18: 396.96 | J18: =E18+H18+I18 -> 9327.21 | L18: 0.6 | M18: =1-L18 -> 0.4 | O18: 0.3 | P18: 0.25 | Q18: 0.15 | R18: 0.2 | S18: 0.1 | AB18: =IFERROR(($J18*O18)*$L18, "") -> 1678.8978 | AC18: =IFERROR(($J18*P18)*$L18, "") -> 1399.0815 | AD18: =IFERROR(($J18*Q18)*$L18, "") -> 839.4489 | AE18: =IFERROR(($J18*R18)*$L18, "") -> 1119.2652 | AF18: =IFERROR(($J18*S18)*$L18, "") -> 559.6326 | AG18: =IFERROR(($J18*T18)*$L18, "") -> 0 | AH18: =IFERROR(($J18*U18)*$L18, "") -> 0 | AI18: =IFERROR(($J18*V18)*$L18, "") -> 0 | ... AM18: =IFERROR(($J18*Z18)*$L18, "") -> 0 | AN18: =IFERROR(SUMIF($AB$4:$AM$4, "RDEC", AB18:AM18), "") -> 1119.2652 | AO18: =IFERROR(SUMIF($AB$4:$AM$4, "SME", AB18:AM18), "") -> 4477.0608 | AP18: =IFERROR(SUMIF($AB$4:$AM$4, "De Minimis", AB18:AM18), "") -> 0 | AR18: =IFERROR(($J18*O18)*$M18, "") -> 1119.2652 | AS18: =IFERROR(($J18*P18)*$M18, "") -> 932.721 | AT18: =IFERROR(($J18*Q18)*$M18, "") -> 559.6326 | AU18: =IFERROR(($J18*R18)*$M18, "") -> 746.1768 | AV18: =IFERROR(($J18*S18)*$M18, "") -> 373.0884 | AW18: =IFERROR(($J18*T18)*$M18, "") -> 0 | AX18: =IFERROR(($J18*U18)*$M18, "") -> 0 | AY18: =IFERROR(($J18*V18)*$M18, "") -> 0 | ... BC18: =IFERROR(($J18*Z18)*$M18, "") -> 0 | BD18: =IFERROR(SUMIF($AB$4:$AM$4, "RDEC", AR18:BC18), "") -> 746.1768 | BE18: =IFERROR(SUMIF($AB$4:$AM$4, "SME", AR18:BC18), "") -> 2984.7072 | BF18: =IFERROR(SUMIF($AB$4:$AM$4, "De Minimis", AR18:BC18), "") -> 0 | BH18: =IF((SUM(O18:Z18)>1),"ERROR","")
D19: =+EDATE(D18, 1) -> 45627 | E19: 7901.59 | F19: 2607.52 | G19: 571.46 | H19: 985.77 | I19: 395.08 | J19: =E19+H19+I19 -> 9282.44 | L19: 0.6 | M19: =1-L19 -> 0.4 | O19: 0.3 | P19: 0.25 | Q19: 0.15 | R19: 0.2 | S19: 0.1 | AB19: =IFERROR(($J19*O19)*$L19, "") -> 1670.8392 | AC19: =IFERROR(($J19*P19)*$L19, "") -> 1392.366 | AD19: =IFERROR(($J19*Q19)*$L19, "") -> 835.4196 | AE19: =IFERROR(($J19*R19)*$L19, "") -> 1113.8928 | AF19: =IFERROR(($J19*S19)*$L19, "") -> 556.9464 | AG19: =IFERROR(($J19*T19)*$L19, "") -> 0 | AH19: =IFERROR(($J19*U19)*$L19, "") -> 0 | AI19: =IFERROR(($J19*V19)*$L19, "") -> 0 | ... AM19: =IFERROR(($J19*Z19)*$L19, "") -> 0 | AN19: =IFERROR(SUMIF($AB$4:$AM$4, "RDEC", AB19:AM19), "") -> 1113.8928 | AO19: =IFERROR(SUMIF($AB$4:$AM$4, "SME", AB19:AM19), "") -> 4455.5712 | AP19: =IFERROR(SUMIF($AB$4:$AM$4, "De Minimis", AB19:AM19), "") -> 0 | AR19: =IFERROR(($J19*O19)*$M19, "") -> 1113.8928 | AS19: =IFERROR(($J19*P19)*$M19, "") -> 928.244 | AT19: =IFERROR(($J19*Q19)*$M19, "") -> 556.9464 | AU19: =IFERROR(($J19*R19)*$M19, "") -> 742.5952 | AV19: =IFERROR(($J19*S19)*$M19, "") -> 371.2976 | AW19: =IFERROR(($J19*T19)*$M19, "") -> 0 | AX19: =IFERROR(($J19*U19)*$M19, "") -> 0 | AY19: =IFERROR(($J19*V19)*$M19, "") -> 0 | ... BC19: =IFERROR(($J19*Z19)*$M19, "") -> 0 | BD19: =IFERROR(SUMIF($AB$4:$AM$4, "RDEC", AR19:BC19), "") -> 742.5952 | BE19: =IFERROR(SUMIF($AB$4:$AM$4, "SME", AR19:BC19), "") -> 2970.3808 | BF19: =IFERROR(SUMIF($AB$4:$AM$4, "De Minimis", AR19:BC19), "") -> 0 | BH19: =IF((SUM(O19:Z19)>1),"ERROR","")
